Traceback (most recent call last):
  File "/Users/fcalado/.conda/envs/jb/lib/python3.11/site-packages/jupyter_cache/executors/utils.py", line 58, in single_nb_execution
    executenb(
  File "/Users/fcalado/.conda/envs/jb/lib/python3.11/site-packages/nbclient/client.py", line 1319, in execute
    return NotebookClient(nb=nb, resources=resources, km=km, **kwargs).execute()
           ^^^^^^^^^^^^^^^^^^^^^^^^^^^^^^^^^^^^^^^^^^^^^^^^^^^^^^^^^^^^^^^^^^^^^
  File "/Users/fcalado/.conda/envs/jb/lib/python3.11/site-packages/jupyter_core/utils/__init__.py", line 165, in wrapped
    return loop.run_until_complete(inner)
           ^^^^^^^^^^^^^^^^^^^^^^^^^^^^^^
  File "/Users/fcalado/.conda/envs/jb/lib/python3.11/asyncio/base_events.py", line 654, in run_until_complete
    return future.result()
           ^^^^^^^^^^^^^^^
  File "/Users/fcalado/.conda/envs/jb/lib/python3.11/site-packages/nbclient/client.py", line 709, in async_execute
    await self.async_execute_cell(
  File "/Users/fcalado/.conda/envs/jb/lib/python3.11/site-packages/nbclient/client.py", line 1062, in async_execute_cell
    await self._check_raise_for_error(cell, cell_index, exec_reply)
  File "/Users/fcalado/.conda/envs/jb/lib/python3.11/site-packages/nbclient/client.py", line 918, in _check_raise_for_error
    raise CellExecutionError.from_cell_and_msg(cell, exec_reply_content)
nbclient.exceptions.CellExecutionError: An error occurred while executing the following cell:
------------------
# functions: type(data)
# methods: just like functions, but with "dot syntax"

type(data)
greeting.upper()
------------------


[0;31m---------------------------------------------------------------------------[0m
[0;31mNameError[0m                                 Traceback (most recent call last)
Cell [0;32mIn[8], line 4[0m
[1;32m      1[0m [38;5;66;03m# functions: type(data)[39;00m
[1;32m      2[0m [38;5;66;03m# methods: just like functions, but with "dot syntax"[39;00m
[0;32m----> 4[0m [38;5;28mtype[39m(data)
[1;32m      5[0m greeting[38;5;241m.[39mupper()

[0;31mNameError[0m: name 'data' is not defined

