Traceback (most recent call last):
  File "/opt/anaconda3/lib/python3.11/site-packages/jupyter_cache/executors/utils.py", line 58, in single_nb_execution
    executenb(
  File "/opt/anaconda3/lib/python3.11/site-packages/nbclient/client.py", line 1305, in execute
    return NotebookClient(nb=nb, resources=resources, km=km, **kwargs).execute()
           ^^^^^^^^^^^^^^^^^^^^^^^^^^^^^^^^^^^^^^^^^^^^^^^^^^^^^^^^^^^^^^^^^^^^^
  File "/opt/anaconda3/lib/python3.11/site-packages/jupyter_core/utils/__init__.py", line 173, in wrapped
    return loop.run_until_complete(inner)
           ^^^^^^^^^^^^^^^^^^^^^^^^^^^^^^
  File "/opt/anaconda3/lib/python3.11/asyncio/base_events.py", line 653, in run_until_complete
    return future.result()
           ^^^^^^^^^^^^^^^
  File "/opt/anaconda3/lib/python3.11/site-packages/nbclient/client.py", line 705, in async_execute
    await self.async_execute_cell(
  File "/opt/anaconda3/lib/python3.11/site-packages/nbclient/client.py", line 1058, in async_execute_cell
    await self._check_raise_for_error(cell, cell_index, exec_reply)
  File "/opt/anaconda3/lib/python3.11/site-packages/nbclient/client.py", line 914, in _check_raise_for_error
    raise CellExecutionError.from_cell_and_msg(cell, exec_reply_content)
nbclient.exceptions.CellExecutionError: An error occurred while executing the following cell:
------------------
soup.find_all('h3').text
------------------


[0;31m---------------------------------------------------------------------------[0m
[0;31mAttributeError[0m                            Traceback (most recent call last)
Cell [0;32mIn[16], line 1[0m
[0;32m----> 1[0m soup[38;5;241m.[39mfind_all([38;5;124m'[39m[38;5;124mh3[39m[38;5;124m'[39m)[38;5;241m.[39mtext

File [0;32m/opt/anaconda3/lib/python3.11/site-packages/bs4/element.py:2428[0m, in [0;36mResultSet.__getattr__[0;34m(self, key)[0m
[1;32m   2426[0m [38;5;28;01mdef[39;00m [38;5;21m__getattr__[39m([38;5;28mself[39m, key):
[1;32m   2427[0m [38;5;250m    [39m[38;5;124;03m"""Raise a helpful exception to explain a common code fix."""[39;00m
[0;32m-> 2428[0m     [38;5;28;01mraise[39;00m [38;5;167;01mAttributeError[39;00m(
[1;32m   2429[0m         [38;5;124m"[39m[38;5;124mResultSet object has no attribute [39m[38;5;124m'[39m[38;5;132;01m%s[39;00m[38;5;124m'[39m[38;5;124m. You[39m[38;5;124m'[39m[38;5;124mre probably treating a list of elements like a single element. Did you call find_all() when you meant to call find()?[39m[38;5;124m"[39m [38;5;241m%[39m key
[1;32m   2430[0m     )

[0;31mAttributeError[0m: ResultSet object has no attribute 'text'. You're probably treating a list of elements like a single element. Did you call find_all() when you meant to call find()?

